Workbook

Sheet 00_README
A1: DeciBridge Economic Validation Model | B1: DeciBridge Economic Validation Model | C1: DeciBridge Economic Validation Model | D1: DeciBridge Economic Validation Model | E1: DeciBridge Economic Validation Model | F1: DeciBridge Economic Validation Model | G1: DeciBridge Economic Validation Model | H1: DeciBridge Economic Validation Model
A2: Gold-standard test workbook for HF_ARNI_ACEI_001; not a final RS Unud HTA decision model. | B2: Gold-standard test workbook for HF_ARNI_ACEI_001; not a final RS Unud HTA decision model. | C2: Gold-standard test workbook for HF_ARNI_ACEI_001; not a final RS Unud HTA decision model. | D2: Gold-standard test workbook for HF_ARNI_ACEI_001; not a final RS Unud HTA decision model. | E2: Gold-standard test workbook for HF_ARNI_ACEI_001; not a final RS Unud HTA decision model. | F2: Gold-standard test workbook for HF_ARNI_ACEI_001; not a final RS Unud HTA decision model. | G2: Gold-standard test workbook for HF_ARNI_ACEI_001; not a final RS Unud HTA decision model. | H2: Gold-standard test workbook for HF_ARNI_ACEI_001; not a final RS Unud HTA decision model.
A4: Purpose and status | B4: Purpose and status | C4: Purpose and status | D4: Purpose and status | E4: Purpose and status | F4: Purpose and status | G4: Purpose and status | H4: Purpose and status
A5: Item | B5: Description
A6: Primary use | B6: Validate DeciBridge calculations for total costs, QALYs, incremental outcomes, ICER, INB/NMB, discounting, BIA, PSA, CE plane, and CEAC.
A7: Case | B7: HF_ARNI_ACEI_001 – Sacubitril/valsartan versus ACE inhibitor.
A8: Model type | B8: Annual decision model with repeated annual values; editable horizon 1–5 years.
A9: Status | B9: SYSTEM-TEST MODEL / ILLUSTRATIVE ASSUMPTIONS – not for final formulary decision.
A10: PSA | B10: 1,000 fixed-uniform simulations (seed 20260724). Dynamic mode follows updated inputs while retaining reproducibility.
A11: Yellow cells | B11: Editable inputs/assumptions.
A12: Blue cells | B12: Calculated cells/formulas.
A14: Model equations | B14: Model equations | C14: Model equations | D14: Model equations | E14: Model equations | F14: Model equations | G14: Model equations | H14: Model equations
A15: Output | B15: Equation
A16: Annual total cost | B16: Annual medicine cost + (rehospitalization probability × HF admission cost) + annual monitoring cost
A17: Annual QALY | B17: Stable-state utility − (rehospitalization probability × QALY loss per admission)
A18: Discounted cost | B18: Annual cost ÷ (1 + cost discount rate)^(year − 1)
A19: Discounted QALY | B19: Annual QALY ÷ (1 + outcome discount rate)^(year − 1)
A20: ICER | B20: (Cost ARNI − Cost ACEI) ÷ (QALY ARNI − QALY ACEI)
A21: INB | B21: (WTP × incremental QALY) − incremental cost
A22: CEAC | B22: Proportion of PSA simulations with positive INB at each WTP threshold
A24: Important limitations | B24: Important limitations | C24: Important limitations | D24: Important limitations | E24: Important limitations | F24: Important limitations | G24: Important limitations | H24: Important limitations
A25: QALY inputs were not available in the uploaded files; utility and QALY loss are explicitly illustrative and editable.
A26: Select Baseline validation to reproduce the original test case, or Dynamic fixed-seed to make PSA and CEAC follow current inputs.
A27: The 12-month RWE rehospitalization proportions are reused for each active model year if the horizon is increased beyond one year.
A28: Mortality, adverse events, treatment discontinuation, and state transitions are not modeled in this test workbook.
A29: All proxy costs must be replaced with validated RS Unud data before policy use.

Sheet 01_INPUTS
A1: Model Inputs – ARNI versus ACEI | B1: Model Inputs – ARNI versus ACEI | C1: Model Inputs – ARNI versus ACEI | D1: Model Inputs – ARNI versus ACEI | E1: Model Inputs – ARNI versus ACEI | F1: Model Inputs – ARNI versus ACEI
A2: Yellow cells are editable. Source status distinguishes observed, proxy, and illustrative assumptions. | B2: Yellow cells are editable. Source status distinguishes observed, proxy, and illustrative assumptions. | C2: Yellow cells are editable. Source status distinguishes observed, proxy, and illustrative assumptions. | D2: Yellow cells are editable. Source status distinguishes observed, proxy, and illustrative assumptions. | E2: Yellow cells are editable. Source status distinguishes observed, proxy, and illustrative assumptions. | F2: Yellow cells are editable. Source status distinguishes observed, proxy, and illustrative assumptions.
A4: Parameter | B4: Base value | C4: Unit | D4: Status | E4: Source | F4: Notes
A5: Case ID | B5: HF_ARNI_ACEI_001 | C5: text | D5: Observed | E5: Uploaded DeciBridge files | F5: Must match across all imported tables.
A6: Time horizon | B6: 1 | C6: years | D6: Test setting | E6: User-defined | F6: Allowed range: 1–5 years.
A7: Cost discount rate | B7: 0.03 | C7: annual proportion | D7: Illustrative | E7: Editable test assumption | F7: Year 1 is not discounted; later years are discounted.
A8: Outcome discount rate | B8: 0.03 | C8: annual proportion | D8: Illustrative | E8: Editable test assumption | F8: Year 1 is not discounted; later years are discounted.
A9: WTP threshold | B9: 85000000 | C9: IDR/QALY | D9: Illustrative | E9: Editable test assumption | F9: Not an official Indonesian threshold.
A10: ARNI rehospitalization probability | B10: 0.45 | C10: annual proportion | D10: Observed RWE | E10: Casepack: 18/40 | F10: 12-month rehospitalization.
A11: ACEI rehospitalization probability | B11: 0.7077 | C11: annual proportion | D11: Observed RWE | E11: Casepack: 46/65 | F11: 12-month rehospitalization.
A12: ARNI median LOS | B12: 4 | C12: days/admission | D12: Observed RWE | E12: Casepack | F12: Secondary clinical validation field.
A13: ACEI median LOS | B13: 5 | C13: days/admission | D13: Observed RWE | E13: Casepack | F13: Secondary clinical validation field.
A14: ARNI annual medicine cost | B14: 15399360 | C14: IDR/patient-year | D14: Proxy | E14: Template: 01_Harga_Obat | F14: Rp21,388/tablet × 60/month × 12.
A15: ACEI annual medicine cost | B15: 324000 | C15: IDR/patient-year | D15: Proxy | E15: Template: 01_Harga_Obat | F15: Rp450/tablet × 60/month × 12.
A16: HF admission cost – base case | B16: 6889093 | C16: IDR/admission | D16: Proxy | E16: Casepack: Biaya Tabanan.xlsx | F16: Median proxy; not RS Unud final.
A17: HF admission cost – alternative | B17: 9105003 | C17: IDR/admission | D17: Proxy | E17: Template: Jogja Hospital 2023 | F17: Mean proxy for scenario checking.
... A27: PSA seed | B27: 20260724 | C27: integer | D27: Fixed | E27: Model specification | F27: Ensures reproducible expected results.
A28: PSA mode | B28: Dynamic fixed-seed | C28: selection | D28: User control | E28: Dropdown | F28: Dynamic follows current inputs; Baseline preserves original validation parameters.

Sheet 02_DETERMINISTIC
A1: Deterministic Cost-Utility Analysis | B1: Deterministic Cost-Utility Analysis | C1: Deterministic Cost-Utility Analysis | D1: Deterministic Cost-Utility Analysis | E1: Deterministic Cost-Utility Analysis | F1: Deterministic Cost-Utility Analysis | G1: Deterministic Cost-Utility Analysis | H1: Deterministic Cost-Utility Analysis | I1: Deterministic Cost-Utility Analysis | J1: Deterministic Cost-Utility Analysis
A2: Formula-driven results. Change yellow cells in 01_INPUTS; all outputs update. | B2: Formula-driven results. Change yellow cells in 01_INPUTS; all outputs update. | C2: Formula-driven results. Change yellow cells in 01_INPUTS; all outputs update. | D2: Formula-driven results. Change yellow cells in 01_INPUTS; all outputs update. | E2: Formula-driven results. Change yellow cells in 01_INPUTS; all outputs update. | F2: Formula-driven results. Change yellow cells in 01_INPUTS; all outputs update. | G2: Formula-driven results. Change yellow cells in 01_INPUTS; all outputs update. | H2: Formula-driven results. Change yellow cells in 01_INPUTS; all outputs update. | I2: Formula-driven results. Change yellow cells in 01_INPUTS; all outputs update. | J2: Formula-driven results. Change yellow cells in 01_INPUTS; all outputs update.
A4: Year | B4: Active? | C4: Cost DF | D4: QALY DF | E4: ARNI cost | F4: ACEI cost | G4: ARNI QALY | H4: ACEI QALY | I4: Incremental cost | J4: Incremental QALY
A5: 1 | B5: =IF(A5<='01_INPUTS'!B6,1,0) -> 1 | C5: =IF(B5=1,1/(1+'01_INPUTS'!B7)^(A5-1),0) -> 1 | D5: =IF(B5=1,1/(1+'01_INPUTS'!B8)^(A5-1),0) -> 1 | E5: =B5*C5*('01_INPUTS'!B14+'01_INPUTS'!B10*'01_INPUTS'!B16+'01_INPUTS'!B20) -> 18499452 | F5: =B5*C5*('01_INPUTS'!B15+'01_INPUTS'!B11*'01_INPUTS'!B16+'01_INPUTS'!B21) -> 5199411.1 | G5: =B5*D5*('01_INPUTS'!B18-'01_INPUTS'!B10*'01_INPUTS'!B19) -> 0.655 | H5: =B5*D5*('01_INPUTS'!B18-'01_INPUTS'!B11*'01_INPUTS'!B19) -> 0.62923 | I5: =E5-F5 -> 13300041 | J5: =G5-H5 -> 0.02577
A6: 2 | B6: =IF(A6<='01_INPUTS'!B6,1,0) -> 0 | C6: =IF(B6=1,1/(1+'01_INPUTS'!B7)^(A6-1),0) -> 0 | D6: =IF(B6=1,1/(1+'01_INPUTS'!B8)^(A6-1),0) -> 0 | E6: =B6*C6*('01_INPUTS'!B14+'01_INPUTS'!B10*'01_INPUTS'!B16+'01_INPUTS'!B20) -> 0 | F6: =B6*C6*('01_INPUTS'!B15+'01_INPUTS'!B11*'01_INPUTS'!B16+'01_INPUTS'!B21) -> 0 | G6: =B6*D6*('01_INPUTS'!B18-'01_INPUTS'!B10*'01_INPUTS'!B19) -> 0 | H6: =B6*D6*('01_INPUTS'!B18-'01_INPUTS'!B11*'01_INPUTS'!B19) -> 0 | I6: =E6-F6 -> 0 | J6: =G6-H6 -> 0
A7: 3 | B7: =IF(A7<='01_INPUTS'!B6,1,0) -> 0 | C7: =IF(B7=1,1/(1+'01_INPUTS'!B7)^(A7-1),0) -> 0 | D7: =IF(B7=1,1/(1+'01_INPUTS'!B8)^(A7-1),0) -> 0 | E7: =B7*C7*('01_INPUTS'!B14+'01_INPUTS'!B10*'01_INPUTS'!B16+'01_INPUTS'!B20) -> 0 | F7: =B7*C7*('01_INPUTS'!B15+'01_INPUTS'!B11*'01_INPUTS'!B16+'01_INPUTS'!B21) -> 0 | G7: =B7*D7*('01_INPUTS'!B18-'01_INPUTS'!B10*'01_INPUTS'!B19) -> 0 | H7: =B7*D7*('01_INPUTS'!B18-'01_INPUTS'!B11*'01_INPUTS'!B19) -> 0 | I7: =E7-F7 -> 0 | J7: =G7-H7 -> 0
A8: 4 | B8: =IF(A8<='01_INPUTS'!B6,1,0) -> 0 | C8: =IF(B8=1,1/(1+'01_INPUTS'!B7)^(A8-1),0) -> 0 | D8: =IF(B8=1,1/(1+'01_INPUTS'!B8)^(A8-1),0) -> 0 | E8: =B8*C8*('01_INPUTS'!B14+'01_INPUTS'!B10*'01_INPUTS'!B16+'01_INPUTS'!B20) -> 0 | F8: =B8*C8*('01_INPUTS'!B15+'01_INPUTS'!B11*'01_INPUTS'!B16+'01_INPUTS'!B21) -> 0 | G8: =B8*D8*('01_INPUTS'!B18-'01_INPUTS'!B10*'01_INPUTS'!B19) -> 0 | H8: =B8*D8*('01_INPUTS'!B18-'01_INPUTS'!B11*'01_INPUTS'!B19) -> 0 | I8: =E8-F8 -> 0 | J8: =G8-H8 -> 0
A9: 5 | B9: =IF(A9<='01_INPUTS'!B6,1,0) -> 0 | C9: =IF(B9=1,1/(1+'01_INPUTS'!B7)^(A9-1),0) -> 0 | D9: =IF(B9=1,1/(1+'01_INPUTS'!B8)^(A9-1),0) -> 0 | E9: =B9*C9*('01_INPUTS'!B14+'01_INPUTS'!B10*'01_INPUTS'!B16+'01_INPUTS'!B20) -> 0 | F9: =B9*C9*('01_INPUTS'!B15+'01_INPUTS'!B11*'01_INPUTS'!B16+'01_INPUTS'!B21) -> 0 | G9: =B9*D9*('01_INPUTS'!B18-'01_INPUTS'!B10*'01_INPUTS'!B19) -> 0 | H9: =B9*D9*('01_INPUTS'!B18-'01_INPUTS'!B11*'01_INPUTS'!B19) -> 0 | I9: =E9-F9 -> 0 | J9: =G9-H9 -> 0
A11: TOTAL | E11: =SUM(E5:E9) -> 18499452 | F11: =SUM(F5:F9) -> 5199411.1 | G11: =SUM(G5:G9) -> 0.655 | H11: =SUM(H5:H9) -> 0.62923 | I11: =SUM(I5:I9) -> 13300041 | J11: =SUM(J5:J9) -> 0.02577
A14: Economic outputs | B14: Economic outputs | C14: Economic outputs | D14: Economic outputs | F14: Clinical validation outputs | G14: Clinical validation outputs | H14: Clinical validation outputs | I14: Clinical validation outputs | J14: Clinical validation outputs
A15: Metric | B15: Value | C15: Unit | D15: Interpretation | F15: Metric | G15: Value | H15: Unit
A16: Total cost – ARNI | B16: =E11 -> 18499452 | C16: IDR/patient | D16: Discounted total | F16: Absolute rehospitalization reduction | G16: ='01_INPUTS'!B11-'01_INPUTS'!B10 -> 0.2577 | H16: proportion
A17: Total cost – ACEI | B17: =F11 -> 5199411.1 | C17: IDR/patient | D17: Discounted total | F17: Relative risk | G17: ='01_INPUTS'!B10/'01_INPUTS'!B11 -> 0.63586265 | H17: RR
A18: Total QALY – ARNI | B18: =G11 -> 0.655 | C18: QALY/patient | D18: Discounted total | F18: Relative risk reduction | G18: =1-G17 -> 0.36413735 | H18: proportion
A19: Total QALY – ACEI | B19: =H11 -> 0.62923 | C19: QALY/patient | D19: Discounted total | F19: NNT (12 months) | G19: =IF(G16=0,"NA",1/G16) -> 3.8804812 | H19: patients
A20: Incremental cost | B20: =I11 -> 13300041 | C20: IDR/patient | D20: ARNI minus ACEI | F20: LOS difference | G20: ='01_INPUTS'!B12-'01_INPUTS'!B13 -> -1 | H20: days
A21: Incremental effectiveness | B21: =J11 -> 0.02577 | C21: QALY/patient | D21: ARNI minus ACEI | F21: Admission cost saving/patient-year | G21: =G16*'01_INPUTS'!B16 -> 1775319.3 | H21: IDR
A22: ICER | B22: =IF(B21=0,"NA",B20/B21) -> 5.1610558e+08 | C22: IDR/QALY | D22: Incremental cost ÷ incremental QALY
A23: INB | B23: ='01_INPUTS'!B9*B21-B20 -> -11109591 | C23: IDR/patient | D23: Positive favors ARNI at selected WTP
A24: Decision at WTP | B24: =IF(B23>0,"Cost-effective at selected WTP","Not cost-effective at selected WTP") -> Not cost-effective at selected WTP | C24: text | D24: Based only on illustrative economic model

Sheet 03_BIA
A1: Budget Impact Scenarios | B1: Budget Impact Scenarios | C1: Budget Impact Scenarios | D1: Budget Impact Scenarios | E1: Budget Impact Scenarios | F1: Budget Impact Scenarios | G1: Budget Impact Scenarios | H1: Budget Impact Scenarios
A2: One-year budget impact for 10%, 30%, and 50% uptake; eligible population is illustrative until replaced. | B2: One-year budget impact for 10%, 30%, and 50% uptake; eligible population is illustrative until replaced. | C2: One-year budget impact for 10%, 30%, and 50% uptake; eligible population is illustrative until replaced. | D2: One-year budget impact for 10%, 30%, and 50% uptake; eligible population is illustrative until replaced. | E2: One-year budget impact for 10%, 30%, and 50% uptake; eligible population is illustrative until replaced. | F2: One-year budget impact for 10%, 30%, and 50% uptake; eligible population is illustrative until replaced. | G2: One-year budget impact for 10%, 30%, and 50% uptake; eligible population is illustrative until replaced. | H2: One-year budget impact for 10%, 30%, and 50% uptake; eligible population is illustrative until replaced.
A4: Scenario | B4: Uptake | C4: Eligible patients | D4: ARNI patients | E4: Drug-only incremental budget | F4: Admission cost offset | G4: Net budget impact | H4: Status
A5: Low | B5: ='01_INPUTS'!B23 -> 0.1 | C5: ='01_INPUTS'!B22 -> 100 | D5: =ROUND(B5*C5,0) -> 10 | E5: =D5*('01_INPUTS'!B14-'01_INPUTS'!B15) -> 150753600 | F5: =D5*('01_INPUTS'!B11-'01_INPUTS'!B10)*'01_INPUTS'!B16 -> 17753193 | G5: =E5-F5+D5*('01_INPUTS'!B20-'01_INPUTS'!B21) -> 1.3300041e+08 | H5: =IF('01_INPUTS'!B22=100,"Illustrative population","User-provided population") -> Illustrative population
A6: Medium | B6: ='01_INPUTS'!B24 -> 0.3 | C6: ='01_INPUTS'!B22 -> 100 | D6: =ROUND(B6*C6,0) -> 30 | E6: =D6*('01_INPUTS'!B14-'01_INPUTS'!B15) -> 452260800 | F6: =D6*('01_INPUTS'!B11-'01_INPUTS'!B10)*'01_INPUTS'!B16 -> 53259578 | G6: =E6-F6+D6*('01_INPUTS'!B20-'01_INPUTS'!B21) -> 3.9900122e+08 | H6: =IF('01_INPUTS'!B22=100,"Illustrative population","User-provided population") -> Illustrative population
A7: High | B7: ='01_INPUTS'!B25 -> 0.5 | C7: ='01_INPUTS'!B22 -> 100 | D7: =ROUND(B7*C7,0) -> 50 | E7: =D7*('01_INPUTS'!B14-'01_INPUTS'!B15) -> 753768000 | F7: =D7*('01_INPUTS'!B11-'01_INPUTS'!B10)*'01_INPUTS'!B16 -> 88765963 | G7: =E7-F7+D7*('01_INPUTS'!B20-'01_INPUTS'!B21) -> 6.6500204e+08 | H7: =IF('01_INPUTS'!B22=100,"Illustrative population","User-provided population") -> Illustrative population
A10: Interpretation | B10: Interpretation | C10: Interpretation | D10: Interpretation | E10: Interpretation | F10: Interpretation | G10: Interpretation | H10: Interpretation
A11: Drug-only budget impact counts medicine cost differences only.
A12: Admission cost offset uses absolute rehospitalization reduction × admission cost.
A13: Net budget impact also adds any difference in annual monitoring cost.
A14: This is a static one-year BIA; population growth, displacement, and multi-year uptake are not included.

Sheet 04_PSA_INPUTS
A1: PSA Distribution Specifications | B1: PSA Distribution Specifications | C1: PSA Distribution Specifications | D1: PSA Distribution Specifications | E1: PSA Distribution Specifications | F1: PSA Distribution Specifications | G1: PSA Distribution Specifications | H1: PSA Distribution Specifications | I1: PSA Distribution Specifications | J1: PSA Distribution Specifications
A2: Active parameters follow the selected PSA mode. Change current inputs only in 01_INPUTS. | B2: Active parameters follow the selected PSA mode. Change current inputs only in 01_INPUTS. | C2: Active parameters follow the selected PSA mode. Change current inputs only in 01_INPUTS. | D2: Active parameters follow the selected PSA mode. Change current inputs only in 01_INPUTS. | E2: Active parameters follow the selected PSA mode. Change current inputs only in 01_INPUTS. | F2: Active parameters follow the selected PSA mode. Change current inputs only in 01_INPUTS. | G2: Active parameters follow the selected PSA mode. Change current inputs only in 01_INPUTS. | H2: Active parameters follow the selected PSA mode. Change current inputs only in 01_INPUTS. | I2: Active parameters follow the selected PSA mode. Change current inputs only in 01_INPUTS. | J2: Active parameters follow the selected PSA mode. Change current inputs only in 01_INPUTS.
A4: Parameter | B4: Distribution | C4: Baseline mean | D4: Current input | E4: Active mean | F4: Uncertainty | G4: Value | H4: Alpha/shape | I4: Beta/scale | J4: Source/status
A5: ARNI rehospitalization | B5: Beta | C5: 0.45 | D5: ='01_INPUTS'!B10 -> 0.45 | E5: =IF('01_INPUTS'!B28="Baseline validation",C5,D5) -> 0.45 | F5: Effective N | G5: 40 | H5: =E5*G5+1 -> 19 | I5: =(1-E5)*G5+1 -> 23 | J5: Observed RWE; uncertainty responds to current probability
A6: ACEI rehospitalization | B6: Beta | C6: 0.7077 | D6: ='01_INPUTS'!B11 -> 0.7077 | E6: =IF('01_INPUTS'!B28="Baseline validation",C6,D6) -> 0.7077 | F6: Effective N | G6: 65 | H6: =E6*G6+1 -> 47.0005 | I6: =(1-E6)*G6+1 -> 19.9995 | J6: Observed RWE; uncertainty responds to current probability
A7: ARNI annual medicine cost | B7: Gamma | C7: 15399360 | D7: ='01_INPUTS'!B14 -> 15399360 | E7: =IF('01_INPUTS'!B28="Baseline validation",C7,D7) -> 15399360 | F7: CV | G7: 0.1 | H7: =1/(G7^2) -> 100 | I7: =E7/H7 -> 153993.6 | J7: Illustrative CV 10%
A8: ACEI annual medicine cost | B8: Gamma | C8: 324000 | D8: ='01_INPUTS'!B15 -> 324000 | E8: =IF('01_INPUTS'!B28="Baseline validation",C8,D8) -> 324000 | F8: CV | G8: 0.1 | H8: =1/(G8^2) -> 100 | I8: =E8/H8 -> 3240 | J8: Illustrative CV 10%
A9: HF admission cost | B9: Gamma | C9: 6889093 | D9: ='01_INPUTS'!B16 -> 6889093 | E9: =IF('01_INPUTS'!B28="Baseline validation",C9,D9) -> 6889093 | F9: CV | G9: 0.2 | H9: =1/(G9^2) -> 25 | I9: =E9/H9 -> 275563.72 | J9: Proxy cost; illustrative CV 20%
A10: Stable utility | B10: Beta | C10: 0.7 | D10: ='01_INPUTS'!B18 -> 0.7 | E10: =IF('01_INPUTS'!B28="Baseline validation",C10,D10) -> 0.7 | F10: SE | G10: 0.03 | H10: =E10*(E10*(1-E10)/(G10^2)-1) -> 162.63333 | I10: =(1-E10)*(E10*(1-E10)/(G10^2)-1) -> 69.7 | J10: Illustrative SE 0.03
A11: QALY loss/admission | B11: Beta | C11: 0.1 | D11: ='01_INPUTS'!B19 -> 0.1 | E11: =IF('01_INPUTS'!B28="Baseline validation",C11,D11) -> 0.1 | F11: SE | G11: 0.02 | H11: =E11*(E11*(1-E11)/(G11^2)-1) -> 22.4 | I11: =(1-E11)*(E11*(1-E11)/(G11^2)-1) -> 201.6 | J11: Illustrative SE 0.02
A14: Mode status | B14: Mode status | C14: Mode status | D14: Mode status | E14: Mode status | F14: Mode status | G14: Mode status | H14: Mode status | I14: Mode status | J14: Mode status
A15: Selected mode | B15: ='01_INPUTS'!B28 -> Dynamic fixed-seed
A16: Behavior | B16: =IF(B15="Baseline validation","Original parameters retained for dashboard regression testing","All active means follow current values in 01_INPUTS") -> All active means follow current values in 01_INPUTS

Sheet 05_PSA_1000
A1: Iteration | B1: p_rehosp_ARNI | C1: p_rehosp_ACEI | D1: DrugCost_ARNI | E1: DrugCost_ACEI | F1: AdmissionCost | G1: StableUtility | H1: QALYLossAdmission | I1: TotalCost_ARNI | J1: TotalCost_ACEI | K1: DeltaCost | L1: QALY_ARNI | M1: QALY_ACEI | N1: DeltaQALY | O1: ICER | P1: INB_at_base_WTP | Q1: CostEffective | R1: U_p_ARNI | S1: U_p_ACEI | T1: U_cost_ARNI | U1: U_cost_ACEI | V1: U_admission | W1: U_utility | X1: U_qaly_loss
A2: 1 | B2: =_xludf.BETA.INV(R2,'04_PSA_INPUTS'!H5,'04_PSA_INPUTS'!I5) -> #NAME? | C2: =_xludf.BETA.INV(S2,'04_PSA_INPUTS'!H6,'04_PSA_INPUTS'!I6) -> #NAME? | D2: =_xludf.GAMMA.INV(T2,'04_PSA_INPUTS'!H7,'04_PSA_INPUTS'!I7) -> #NAME? | E2: =_xludf.GAMMA.INV(U2,'04_PSA_INPUTS'!H8,'04_PSA_INPUTS'!I8) -> #NAME? | F2: =_xludf.GAMMA.INV(V2,'04_PSA_INPUTS'!H9,'04_PSA_INPUTS'!I9) -> #NAME? | G2: =_xludf.BETA.INV(W2,'04_PSA_INPUTS'!H10,'04_PSA_INPUTS'!I10) -> #NAME? | H2: =_xludf.BETA.INV(X2,'04_PSA_INPUTS'!H11,'04_PSA_INPUTS'!I11) -> #NAME? | I2: =D2+B2*F2+'01_INPUTS'!B20 -> #NAME? | J2: =E2+C2*F2+'01_INPUTS'!B21 -> #NAME? | K2: =I2-J2 -> #NAME? | L2: =G2-B2*H2 -> #NAME? | M2: =G2-C2*H2 -> #NAME? | N2: =L2-M2 -> #NAME? | O2: =IF(N2=0,"",K2/N2) -> #NAME? | P2: ='01_INPUTS'!B9*N2-K2 -> #NAME? | Q2: =IF(P2>0,1,0) -> #NAME? | R2: 0.59542984 | S2: 0.85337417 | T2: 0.85474902 | U2: 0.80741449 | V2: 0.97727951 | W2: 0.87234909 | X2: 0.85758323
A3: 2 | B3: =_xludf.BETA.INV(R3,'04_PSA_INPUTS'!H5,'04_PSA_INPUTS'!I5) -> #NAME? | C3: =_xludf.BETA.INV(S3,'04_PSA_INPUTS'!H6,'04_PSA_INPUTS'!I6) -> #NAME? | D3: =_xludf.GAMMA.INV(T3,'04_PSA_INPUTS'!H7,'04_PSA_INPUTS'!I7) -> #NAME? | E3: =_xludf.GAMMA.INV(U3,'04_PSA_INPUTS'!H8,'04_PSA_INPUTS'!I8) -> #NAME? | F3: =_xludf.GAMMA.INV(V3,'04_PSA_INPUTS'!H9,'04_PSA_INPUTS'!I9) -> #NAME? | G3: =_xludf.BETA.INV(W3,'04_PSA_INPUTS'!H10,'04_PSA_INPUTS'!I10) -> #NAME? | H3: =_xludf.BETA.INV(X3,'04_PSA_INPUTS'!H11,'04_PSA_INPUTS'!I11) -> #NAME? | I3: =D3+B3*F3+'01_INPUTS'!B20 -> #NAME? | J3: =E3+C3*F3+'01_INPUTS'!B21 -> #NAME? | K3: =I3-J3 -> #NAME? | L3: =G3-B3*H3 -> #NAME? | M3: =G3-C3*H3 -> #NAME? | N3: =L3-M3 -> #NAME? | O3: =IF(N3=0,"",K3/N3) -> #NAME? | P3: ='01_INPUTS'!B9*N3-K3 -> #NAME? | Q3: =IF(P3>0,1,0) -> #NAME? | R3: 0.77433389 | S3: 0.39597799 | T3: 0.40293736 | U3: 0.7103226 | V3: 0.42011354 | W3: 0.34255354 | X3: 0.26147472
A4: 3 | B4: =_xludf.BETA.INV(R4,'04_PSA_INPUTS'!H5,'04_PSA_INPUTS'!I5) -> #NAME? | C4: =_xludf.BETA.INV(S4,'04_PSA_INPUTS'!H6,'04_PSA_INPUTS'!I6) -> #NAME? | D4: =_xludf.GAMMA.INV(T4,'04_PSA_INPUTS'!H7,'04_PSA_INPUTS'!I7) -> #NAME? | E4: =_xludf.GAMMA.INV(U4,'04_PSA_INPUTS'!H8,'04_PSA_INPUTS'!I8) -> #NAME? | F4: =_xludf.GAMMA.INV(V4,'04_PSA_INPUTS'!H9,'04_PSA_INPUTS'!I9) -> #NAME? | G4: =_xludf.BETA.INV(W4,'04_PSA_INPUTS'!H10,'04_PSA_INPUTS'!I10) -> #NAME? | H4: =_xludf.BETA.INV(X4,'04_PSA_INPUTS'!H11,'04_PSA_INPUTS'!I11) -> #NAME? | I4: =D4+B4*F4+'01_INPUTS'!B20 -> #NAME? | J4: =E4+C4*F4+'01_INPUTS'!B21 -> #NAME? | K4: =I4-J4 -> #NAME? | L4: =G4-B4*H4 -> #NAME? | M4: =G4-C4*H4 -> #NAME? | N4: =L4-M4 -> #NAME? | O4: =IF(N4=0,"",K4/N4) -> #NAME? | P4: ='01_INPUTS'!B9*N4-K4 -> #NAME? | Q4: =IF(P4>0,1,0) -> #NAME? | R4: 0.5651422 | S4: 0.82894488 | T4: 0.43205855 | U4: 0.38104961 | V4: 0.83900348 | W4: 0.20886718 | X4: 0.17588501
A5: 4 | B5: =_xludf.BETA.INV(R5,'04_PSA_INPUTS'!H5,'04_PSA_INPUTS'!I5) -> #NAME? | C5: =_xludf.BETA.INV(S5,'04_PSA_INPUTS'!H6,'04_PSA_INPUTS'!I6) -> #NAME? | D5: =_xludf.GAMMA.INV(T5,'04_PSA_INPUTS'!H7,'04_PSA_INPUTS'!I7) -> #NAME? | E5: =_xludf.GAMMA.INV(U5,'04_PSA_INPUTS'!H8,'04_PSA_INPUTS'!I8) -> #NAME? | F5: =_xludf.GAMMA.INV(V5,'04_PSA_INPUTS'!H9,'04_PSA_INPUTS'!I9) -> #NAME? | G5: =_xludf.BETA.INV(W5,'04_PSA_INPUTS'!H10,'04_PSA_INPUTS'!I10) -> #NAME? | H5: =_xludf.BETA.INV(X5,'04_PSA_INPUTS'!H11,'04_PSA_INPUTS'!I11) -> #NAME? | I5: =D5+B5*F5+'01_INPUTS'!B20 -> #NAME? | J5: =E5+C5*F5+'01_INPUTS'!B21 -> #NAME? | K5: =I5-J5 -> #NAME? | L5: =G5-B5*H5 -> #NAME? | M5: =G5-C5*H5 -> #NAME? | N5: =L5-M5 -> #NAME? | O5: =IF(N5=0,"",K5/N5) -> #NAME? | P5: ='01_INPUTS'!B9*N5-K5 -> #NAME? | Q5: =IF(P5>0,1,0) -> #NAME? | R5: 0.34360758 | S5: 0.71049677 | T5: 0.87053893 | U5: 0.58722469 | V5: 0.25799171 | W5: 0.18662832 | X5: 0.36372541
A6: 5 | B6: =_xludf.BETA.INV(R6,'04_PSA_INPUTS'!H5,'04_PSA_INPUTS'!I5) -> #NAME? | C6: =_xludf.BETA.INV(S6,'04_PSA_INPUTS'!H6,'04_PSA_INPUTS'!I6) -> #NAME? | D6: =_xludf.GAMMA.INV(T6,'04_PSA_INPUTS'!H7,'04_PSA_INPUTS'!I7) -> #NAME? | E6: =_xludf.GAMMA.INV(U6,'04_PSA_INPUTS'!H8,'04_PSA_INPUTS'!I8) -> #NAME? | F6: =_xludf.GAMMA.INV(V6,'04_PSA_INPUTS'!H9,'04_PSA_INPUTS'!I9) -> #NAME? | G6: =_xludf.BETA.INV(W6,'04_PSA_INPUTS'!H10,'04_PSA_INPUTS'!I10) -> #NAME? | H6: =_xludf.BETA.INV(X6,'04_PSA_INPUTS'!H11,'04_PSA_INPUTS'!I11) -> #NAME? | I6: =D6+B6*F6+'01_INPUTS'!B20 -> #NAME? | J6: =E6+C6*F6+'01_INPUTS'!B21 -> #NAME? | K6: =I6-J6 -> #NAME? | L6: =G6-B6*H6 -> #NAME? | M6: =G6-C6*H6 -> #NAME? | N6: =L6-M6 -> #NAME? | O6: =IF(N6=0,"",K6/N6) -> #NAME? | P6: ='01_INPUTS'!B9*N6-K6 -> #NAME? | Q6: =IF(P6>0,1,0) -> #NAME? | R6: 0.0094469818 | S6: 0.13853907 | T6: 0.17702434 | U6: 0.67983699 | V6: 0.37754766 | W6: 0.90289794 | X6: 0.15275539
A7: 6 | B7: =_xludf.BETA.INV(R7,'04_PSA_INPUTS'!H5,'04_PSA_INPUTS'!I5) -> #NAME? | C7: =_xludf.BETA.INV(S7,'04_PSA_INPUTS'!H6,'04_PSA_INPUTS'!I6) -> #NAME? | D7: =_xludf.GAMMA.INV(T7,'04_PSA_INPUTS'!H7,'04_PSA_INPUTS'!I7) -> #NAME? | E7: =_xludf.GAMMA.INV(U7,'04_PSA_INPUTS'!H8,'04_PSA_INPUTS'!I8) -> #NAME? | F7: =_xludf.GAMMA.INV(V7,'04_PSA_INPUTS'!H9,'04_PSA_INPUTS'!I9) -> #NAME? | G7: =_xludf.BETA.INV(W7,'04_PSA_INPUTS'!H10,'04_PSA_INPUTS'!I10) -> #NAME? | H7: =_xludf.BETA.INV(X7,'04_PSA_INPUTS'!H11,'04_PSA_INPUTS'!I11) -> #NAME? | I7: =D7+B7*F7+'01_INPUTS'!B20 -> #NAME? | J7: =E7+C7*F7+'01_INPUTS'!B21 -> #NAME? | K7: =I7-J7 -> #NAME? | L7: =G7-B7*H7 -> #NAME? | M7: =G7-C7*H7 -> #NAME? | N7: =L7-M7 -> #NAME? | O7: =IF(N7=0,"",K7/N7) -> #NAME? | P7: ='01_INPUTS'!B9*N7-K7 -> #NAME? | Q7: =IF(P7>0,1,0) -> #NAME? | R7: 0.35481747 | S7: 0.38531392 | T7: 0.89068506 | U7: 0.5445113 | V7: 0.9707977 | W7: 0.83096633 | X7: 0.99970181
A8: 7 | B8: =_xludf.BETA.INV(R8,'04_PSA_INPUTS'!H5,'04_PSA_INPUTS'!I5) -> #NAME? | C8: =_xludf.BETA.INV(S8,'04_PSA_INPUTS'!H6,'04_PSA_INPUTS'!I6) -> #NAME? | D8: =_xludf.GAMMA.INV(T8,'04_PSA_INPUTS'!H7,'04_PSA_INPUTS'!I7) -> #NAME? | E8: =_xludf.GAMMA.INV(U8,'04_PSA_INPUTS'!H8,'04_PSA_INPUTS'!I8) -> #NAME? | F8: =_xludf.GAMMA.INV(V8,'04_PSA_INPUTS'!H9,'04_PSA_INPUTS'!I9) -> #NAME? | G8: =_xludf.BETA.INV(W8,'04_PSA_INPUTS'!H10,'04_PSA_INPUTS'!I10) -> #NAME? | H8: =_xludf.BETA.INV(X8,'04_PSA_INPUTS'!H11,'04_PSA_INPUTS'!I11) -> #NAME? | I8: =D8+B8*F8+'01_INPUTS'!B20 -> #NAME? | J8: =E8+C8*F8+'01_INPUTS'!B21 -> #NAME? | K8: =I8-J8 -> #NAME? | L8: =G8-B8*H8 -> #NAME? | M8: =G8-C8*H8 -> #NAME? | N8: =L8-M8 -> #NAME? | O8: =IF(N8=0,"",K8/N8) -> #NAME? | P8: ='01_INPUTS'!B9*N8-K8 -> #NAME? | Q8: =IF(P8>0,1,0) -> #NAME? | R8: 0.97384578 | S8: 0.049857999 | T8: 0.98408977 | U8: 0.36080815 | V8: 0.49235751 | W8: 0.011080653 | X8: 0.41827401
A9: 8 | B9: =_xludf.BETA.INV(R9,'04_PSA_INPUTS'!H5,'04_PSA_INPUTS'!I5) -> #NAME? | C9: =_xludf.BETA.INV(S9,'04_PSA_INPUTS'!H6,'04_PSA_INPUTS'!I6) -> #NAME? | D9: =_xludf.GAMMA.INV(T9,'04_PSA_INPUTS'!H7,'04_PSA_INPUTS'!I7) -> #NAME? | E9: =_xludf.GAMMA.INV(U9,'04_PSA_INPUTS'!H8,'04_PSA_INPUTS'!I8) -> #NAME? | F9: =_xludf.GAMMA.INV(V9,'04_PSA_INPUTS'!H9,'04_PSA_INPUTS'!I9) -> #NAME? | G9: =_xludf.BETA.INV(W9,'04_PSA_INPUTS'!H10,'04_PSA_INPUTS'!I10) -> #NAME? | H9: =_xludf.BETA.INV(X9,'04_PSA_INPUTS'!H11,'04_PSA_INPUTS'!I11) -> #NAME? | I9: =D9+B9*F9+'01_INPUTS'!B20 -> #NAME? | J9: =E9+C9*F9+'01_INPUTS'!B21 -> #NAME? | K9: =I9-J9 -> #NAME? | L9: =G9-B9*H9 -> #NAME? | M9: =G9-C9*H9 -> #NAME? | N9: =L9-M9 -> #NAME? | O9: =IF(N9=0,"",K9/N9) -> #NAME? | P9: ='01_INPUTS'!B9*N9-K9 -> #NAME? | Q9: =IF(P9>0,1,0) -> #NAME? | R9: 0.56894008 | S9: 0.33330683 | T9: 0.51246177 | U9: 0.4215151 | V9: 0.81069763 | W9: 0.31157325 | X9: 0.14950265
A10: 9 | B10: =_xludf.BETA.INV(R10,'04_PSA_INPUTS'!H5,'04_PSA_INPUTS'!I5) -> #NAME? | C10: =_xludf.BETA.INV(S10,'04_PSA_INPUTS'!H6,'04_PSA_INPUTS'!I6) -> #NAME? | D10: =_xludf.GAMMA.INV(T10,'04_PSA_INPUTS'!H7,'04_PSA_INPUTS'!I7) -> #NAME? | E10: =_xludf.GAMMA.INV(U10,'04_PSA_INPUTS'!H8,'04_PSA_INPUTS'!I8) -> #NAME? | F10: =_xludf.GAMMA.INV(V10,'04_PSA_INPUTS'!H9,'04_PSA_INPUTS'!I9) -> #NAME? | G10: =_xludf.BETA.INV(W10,'04_PSA_INPUTS'!H10,'04_PSA_INPUTS'!I10) -> #NAME? | H10: =_xludf.BETA.INV(X10,'04_PSA_INPUTS'!H11,'04_PSA_INPUTS'!I11) -> #NAME? | I10: =D10+B10*F10+'01_INPUTS'!B20 -> #NAME? | J10: =E10+C10*F10+'01_INPUTS'!B21 -> #NAME? | K10: =I10-J10 -> #NAME? | L10: =G10-B10*H10 -> #NAME? | M10: =G10-C10*H10 -> #NAME? | N10: =L10-M10 -> #NAME? | O10: =IF(N10=0,"",K10/N10) -> #NAME? | P10: ='01_INPUTS'!B9*N10-K10 -> #NAME? | Q10: =IF(P10>0,1,0) -> #NAME? | R10: 0.80603485 | S10: 0.63524625 | T10: 0.49112567 | U10: 0.15584527 | V10: 0.79029972 | W10: 0.83961507 | X10: 0.84839473
A11: 10 | B11: =_xludf.BETA.INV(R11,'04_PSA_INPUTS'!H5,'04_PSA_INPUTS'!I5) -> #NAME? | C11: =_xludf.BETA.INV(S11,'04_PSA_INPUTS'!H6,'04_PSA_INPUTS'!I6) -> #NAME? | D11: =_xludf.GAMMA.INV(T11,'04_PSA_INPUTS'!H7,'04_PSA_INPUTS'!I7) -> #NAME? | E11: =_xludf.GAMMA.INV(U11,'04_PSA_INPUTS'!H8,'04_PSA_INPUTS'!I8) -> #NAME? | F11: =_xludf.GAMMA.INV(V11,'04_PSA_INPUTS'!H9,'04_PSA_INPUTS'!I9) -> #NAME? | G11: =_xludf.BETA.INV(W11,'04_PSA_INPUTS'!H10,'04_PSA_INPUTS'!I10) -> #NAME? | H11: =_xludf.BETA.INV(X11,'04_PSA_INPUTS'!H11,'04_PSA_INPUTS'!I11) -> #NAME? | I11: =D11+B11*F11+'01_INPUTS'!B20 -> #NAME? | J11: =E11+C11*F11+'01_INPUTS'!B21 -> #NAME? | K11: =I11-J11 -> #NAME? | L11: =G11-B11*H11 -> #NAME? | M11: =G11-C11*H11 -> #NAME? | N11: =L11-M11 -> #NAME? | O11: =IF(N11=0,"",K11/N11) -> #NAME? | P11: ='01_INPUTS'!B9*N11-K11 -> #NAME? | Q11: =IF(P11>0,1,0) -> #NAME? | R11: 0.5483465 | S11: 0.92545174 | T11: 0.22026996 | U11: 0.79709808 | V11: 0.037196886 | W11: 0.95171876 | X11: 0.20807444
A12: 11 | B12: =_xludf.BETA.INV(R12,'04_PSA_INPUTS'!H5,'04_PSA_INPUTS'!I5) -> #NAME? | C12: =_xludf.BETA.INV(S12,'04_PSA_INPUTS'!H6,'04_PSA_INPUTS'!I6) -> #NAME? | D12: =_xludf.GAMMA.INV(T12,'04_PSA_INPUTS'!H7,'04_PSA_INPUTS'!I7) -> #NAME? | E12: =_xludf.GAMMA.INV(U12,'04_PSA_INPUTS'!H8,'04_PSA_INPUTS'!I8) -> #NAME? | F12: =_xludf.GAMMA.INV(V12,'04_PSA_INPUTS'!H9,'04_PSA_INPUTS'!I9) -> #NAME? | G12: =_xludf.BETA.INV(W12,'04_PSA_INPUTS'!H10,'04_PSA_INPUTS'!I10) -> #NAME? | H12: =_xludf.BETA.INV(X12,'04_PSA_INPUTS'!H11,'04_PSA_INPUTS'!I11) -> #NAME? | I12: =D12+B12*F12+'01_INPUTS'!B20 -> #NAME? | J12: =E12+C12*F12+'01_INPUTS'!B21 -> #NAME? | K12: =I12-J12 -> #NAME? | L12: =G12-B12*H12 -> #NAME? | M12: =G12-C12*H12 -> #NAME? | N12: =L12-M12 -> #NAME? | O12: =IF(N12=0,"",K12/N12) -> #NAME? | P12: ='01_INPUTS'!B9*N12-K12 -> #NAME? | Q12: =IF(P12>0,1,0) -> #NAME? | R12: 0.5248102 | S12: 0.51498771 | T12: 0.15554826 | U12: 0.93610191 | V12: 0.16751501 | W12: 0.84223013 | X12: 0.15109838
A13: 12 | B13: =_xludf.BETA.INV(R13,'04_PSA_INPUTS'!H5,'04_PSA_INPUTS'!I5) -> #NAME? | C13: =_xludf.BETA.INV(S13,'04_PSA_INPUTS'!H6,'04_PSA_INPUTS'!I6) -> #NAME? | D13: =_xludf.GAMMA.INV(T13,'04_PSA_INPUTS'!H7,'04_PSA_INPUTS'!I7) -> #NAME? | E13: =_xludf.GAMMA.INV(U13,'04_PSA_INPUTS'!H8,'04_PSA_INPUTS'!I8) -> #NAME? | F13: =_xludf.GAMMA.INV(V13,'04_PSA_INPUTS'!H9,'04_PSA_INPUTS'!I9) -> #NAME? | G13: =_xludf.BETA.INV(W13,'04_PSA_INPUTS'!H10,'04_PSA_INPUTS'!I10) -> #NAME? | H13: =_xludf.BETA.INV(X13,'04_PSA_INPUTS'!H11,'04_PSA_INPUTS'!I11) -> #NAME? | I13: =D13+B13*F13+'01_INPUTS'!B20 -> #NAME? | J13: =E13+C13*F13+'01_INPUTS'!B21 -> #NAME? | K13: =I13-J13 -> #NAME? | L13: =G13-B13*H13 -> #NAME? | M13: =G13-C13*H13 -> #NAME? | N13: =L13-M13 -> #NAME? | O13: =IF(N13=0,"",K13/N13) -> #NAME? | P13: ='01_INPUTS'!B9*N13-K13 -> #NAME? | Q13: =IF(P13>0,1,0) -> #NAME? | R13: 0.91630495 | S13: 0.79980992 | T13: 0.50627315 | U13: 0.33772049 | V13: 0.42095801 | W13: 0.90187859 | X13: 0.28751272
A14: 13 | B14: =_xludf.BETA.INV(R14,'04_PSA_INPUTS'!H5,'04_PSA_INPUTS'!I5) -> #NAME? | C14: =_xludf.BETA.INV(S14,'04_PSA_INPUTS'!H6,'04_PSA_INPUTS'!I6) -> #NAME? | D14: =_xludf.GAMMA.INV(T14,'04_PSA_INPUTS'!H7,'04_PSA_INPUTS'!I7) -> #NAME? | E14: =_xludf.GAMMA.INV(U14,'04_PSA_INPUTS'!H8,'04_PSA_INPUTS'!I8) -> #NAME? | F14: =_xludf.GAMMA.INV(V14,'04_PSA_INPUTS'!H9,'04_PSA_INPUTS'!I9) -> #NAME? | G14: =_xludf.BETA.INV(W14,'04_PSA_INPUTS'!H10,'04_PSA_INPUTS'!I10) -> #NAME? | H14: =_xludf.BETA.INV(X14,'04_PSA_INPUTS'!H11,'04_PSA_INPUTS'!I11) -> #NAME? | I14: =D14+B14*F14+'01_INPUTS'!B20 -> #NAME? | J14: =E14+C14*F14+'01_INPUTS'!B21 -> #NAME? | K14: =I14-J14 -> #NAME? | L14: =G14-B14*H14 -> #NAME? | M14: =G14-C14*H14 -> #NAME? | N14: =L14-M14 -> #NAME? | O14: =IF(N14=0,"",K14/N14) -> #NAME? | P14: ='01_INPUTS'!B9*N14-K14 -> #NAME? | Q14: =IF(P14>0,1,0) -> #NAME? | R14: 0.40605669 | S14: 0.32619334 | T14: 0.43881465 | U14: 0.18029065 | V14: 0.90321131 | W14: 0.36014099 | X14: 0.0062810294
A15: 14 | B15: =_xludf.BETA.INV(R15,'04_PSA_INPUTS'!H5,'04_PSA_INPUTS'!I5) -> #NAME? | C15: =_xludf.BETA.INV(S15,'04_PSA_INPUTS'!H6,'04_PSA_INPUTS'!I6) -> #NAME? | D15: =_xludf.GAMMA.INV(T15,'04_PSA_INPUTS'!H7,'04_PSA_INPUTS'!I7) -> #NAME? | E15: =_xludf.GAMMA.INV(U15,'04_PSA_INPUTS'!H8,'04_PSA_INPUTS'!I8) -> #NAME? | F15: =_xludf.GAMMA.INV(V15,'04_PSA_INPUTS'!H9,'04_PSA_INPUTS'!I9) -> #NAME? | G15: =_xludf.BETA.INV(W15,'04_PSA_INPUTS'!H10,'04_PSA_INPUTS'!I10) -> #NAME? | H15: =_xludf.BETA.INV(X15,'04_PSA_INPUTS'!H11,'04_PSA_INPUTS'!I11) -> #NAME? | I15: =D15+B15*F15+'01_INPUTS'!B20 -> #NAME? | J15: =E15+C15*F15+'01_INPUTS'!B21 -> #NAME? | K15: =I15-J15 -> #NAME? | L15: =G15-B15*H15 -> #NAME? | M15: =G15-C15*H15 -> #NAME? | N15: =L15-M15 -> #NAME? | O15: =IF(N15=0,"",K15/N15) -> #NAME? | P15: ='01_INPUTS'!B9*N15-K15 -> #NAME? | Q15: =IF(P15>0,1,0) -> #NAME? | R15: 0.87412803 | S15: 0.76323962 | T15: 0.90191245 | U15: 0.41939342 | V15: 0.48104646 | W15: 0.50956619 | X15: 0.55092532
A16: 15 | B16: =_xludf.BETA.INV(R16,'04_PSA_INPUTS'!H5,'04_PSA_INPUTS'!I5) -> #NAME? | C16: =_xludf.BETA.INV(S16,'04_PSA_INPUTS'!H6,'04_PSA_INPUTS'!I6) -> #NAME? | D16: =_xludf.GAMMA.INV(T16,'04_PSA_INPUTS'!H7,'04_PSA_INPUTS'!I7) -> #NAME? | E16: =_xludf.GAMMA.INV(U16,'04_PSA_INPUTS'!H8,'04_PSA_INPUTS'!I8) -> #NAME? | F16: =_xludf.GAMMA.INV(V16,'04_PSA_INPUTS'!H9,'04_PSA_INPUTS'!I9) -> #NAME? | G16: =_xludf.BETA.INV(W16,'04_PSA_INPUTS'!H10,'04_PSA_INPUTS'!I10) -> #NAME? | H16: =_xludf.BETA.INV(X16,'04_PSA_INPUTS'!H11,'04_PSA_INPUTS'!I11) -> #NAME? | I16: =D16+B16*F16+'01_INPUTS'!B20 -> #NAME? | J16: =E16+C16*F16+'01_INPUTS'!B21 -> #NAME? | K16: =I16-J16 -> #NAME? | L16: =G16-B16*H16 -> #NAME? | M16: =G16-C16*H16 -> #NAME? | N16: =L16-M16 -> #NAME? | O16: =IF(N16=0,"",K16/N16) -> #NAME? | P16: ='01_INPUTS'!B9*N16-K16 -> #NAME? | Q16: =IF(P16>0,1,0) -> #NAME? | R16: 0.48684134 | S16: 0.28072798 | T16: 0.57817117 | U16: 0.6263273 | V16: 0.6132418 | W16: 0.4329998 | X16: 0.57236792
A17: 16 | B17: =_xludf.BETA.INV(R17,'04_PSA_INPUTS'!H5,'04_PSA_INPUTS'!I5) -> #NAME? | C17: =_xludf.BETA.INV(S17,'04_PSA_INPUTS'!H6,'04_PSA_INPUTS'!I6) -> #NAME? | D17: =_xludf.GAMMA.INV(T17,'04_PSA_INPUTS'!H7,'04_PSA_INPUTS'!I7) -> #NAME? | E17: =_xludf.GAMMA.INV(U17,'04_PSA_INPUTS'!H8,'04_PSA_INPUTS'!I8) -> #NAME? | F17: =_xludf.GAMMA.INV(V17,'04_PSA_INPUTS'!H9,'04_PSA_INPUTS'!I9) -> #NAME? | G17: =_xludf.BETA.INV(W17,'04_PSA_INPUTS'!H10,'04_PSA_INPUTS'!I10) -> #NAME? | H17: =_xludf.BETA.INV(X17,'04_PSA_INPUTS'!H11,'04_PSA_INPUTS'!I11) -> #NAME? | I17: =D17+B17*F17+'01_INPUTS'!B20 -> #NAME? | J17: =E17+C17*F17+'01_INPUTS'!B21 -> #NAME? | K17: =I17-J17 -> #NAME? | L17: =G17-B17*H17 -> #NAME? | M17: =G17-C17*H17 -> #NAME? | N17: =L17-M17 -> #NAME? | O17: =IF(N17=0,"",K17/N17) -> #NAME? | P17: ='01_INPUTS'!B9*N17-K17 -> #NAME? | Q17: =IF(P17>0,1,0) -> #NAME? | R17: 0.46217532 | S17: 0.67562501 | T17: 0.24186856 | U17: 0.01028772 | V17: 0.0062165749 | W17: 0.32776461 | X17: 0.66877373
A18: 17 | B18: =_xludf.BETA.INV(R18,'04_PSA_INPUTS'!H5,'04_PSA_INPUTS'!I5) -> #NAME? | C18: =_xludf.BETA.INV(S18,'04_PSA_INPUTS'!H6,'04_PSA_INPUTS'!I6) -> #NAME? | D18: =_xludf.GAMMA.INV(T18,'04_PSA_INPUTS'!H7,'04_PSA_INPUTS'!I7) -> #NAME? | E18: =_xludf.GAMMA.INV(U18,'04_PSA_INPUTS'!H8,'04_PSA_INPUTS'!I8) -> #NAME? | F18: =_xludf.GAMMA.INV(V18,'04_PSA_INPUTS'!H9,'04_PSA_INPUTS'!I9) -> #NAME? | G18: =_xludf.BETA.INV(W18,'04_PSA_INPUTS'!H10,'04_PSA_INPUTS'!I10) -> #NAME? | H18: =_xludf.BETA.INV(X18,'04_PSA_INPUTS'!H11,'04_PSA_INPUTS'!I11) -> #NAME? | I18: =D18+B18*F18+'01_INPUTS'!B20 -> #NAME? | J18: =E18+C18*F18+'01_INPUTS'!B21 -> #NAME? | K18: =I18-J18 -> #NAME? | L18: =G18-B18*H18 -> #NAME? | M18: =G18-C18*H18 -> #NAME? | N18: =L18-M18 -> #NAME? | O18: =IF(N18=0,"",K18/N18) -> #NAME? | P18: ='01_INPUTS'!B9*N18-K18 -> #NAME? | Q18: =IF(P18>0,1,0) -> #NAME? | R18: 0.30768241 | S18: 0.23279399 | T18: 0.58335451 | U18: 0.32894357 | V18: 0.94068828 | W18: 0.70336181 | X18: 0.065895996
A19: 18 | B19: =_xludf.BETA.INV(R19,'04_PSA_INPUTS'!H5,'04_PSA_INPUTS'!I5) -> #NAME? | C19: =_xludf.BETA.INV(S19,'04_PSA_INPUTS'!H6,'04_PSA_INPUTS'!I6) -> #NAME? | D19: =_xludf.GAMMA.INV(T19,'04_PSA_INPUTS'!H7,'04_PSA_INPUTS'!I7) -> #NAME? | E19: =_xludf.GAMMA.INV(U19,'04_PSA_INPUTS'!H8,'04_PSA_INPUTS'!I8) -> #NAME? | F19: =_xludf.GAMMA.INV(V19,'04_PSA_INPUTS'!H9,'04_PSA_INPUTS'!I9) -> #NAME? | G19: =_xludf.BETA.INV(W19,'04_PSA_INPUTS'!H10,'04_PSA_INPUTS'!I10) -> #NAME? | H19: =_xludf.BETA.INV(X19,'04_PSA_INPUTS'!H11,'04_PSA_INPUTS'!I11) -> #NAME? | I19: =D19+B19*F19+'01_INPUTS'!B20 -> #NAME? | J19: =E19+C19*F19+'01_INPUTS'!B21 -> #NAME? | K19: =I19-J19 -> #NAME? | L19: =G19-B19*H19 -> #NAME? | M19: =G19-C19*H19 -> #NAME? | N19: =L19-M19 -> #NAME? | O19: =IF(N19=0,"",K19/N19) -> #NAME? | P19: ='01_INPUTS'!B9*N19-K19 -> #NAME? | Q19: =IF(P19>0,1,0) -> #NAME? | R19: 0.060064552 | S19: 0.2605299 | T19: 0.35653109 | U19: 0.8570683 | V19: 0.13567876 | W19: 0.14050025 | X19: 0.58545119
A20: 19 | B20: =_xludf.BETA.INV(R20,'04_PSA_INPUTS'!H5,'04_PSA_INPUTS'!I5) -> #NAME? | C20: =_xludf.BETA.INV(S20,'04_PSA_INPUTS'!H6,'04_PSA_INPUTS'!I6) -> #NAME? | D20: =_xludf.GAMMA.INV(T20,'04_PSA_INPUTS'!H7,'04_PSA_INPUTS'!I7) -> #NAME? | E20: =_xludf.GAMMA.INV(U20,'04_PSA_INPUTS'!H8,'04_PSA_INPUTS'!I8) -> #NAME? | F20: =_xludf.GAMMA.INV(V20,'04_PSA_INPUTS'!H9,'04_PSA_INPUTS'!I9) -> #NAME? | G20: =_xludf.BETA.INV(W20,'04_PSA_INPUTS'!H10,'04_PSA_INPUTS'!I10) -> #NAME? | H20: =_xludf.BETA.INV(X20,'04_PSA_INPUTS'!H11,'04_PSA_INPUTS'!I11) -> #NAME? | I20: =D20+B20*F20+'01_INPUTS'!B20 -> #NAME? | J20: =E20+C20*F20+'01_INPUTS'!B21 -> #NAME? | K20: =I20-J20 -> #NAME? | L20: =G20-B20*H20 -> #NAME? | M20: =G20-C20*H20 -> #NAME? | N20: =L20-M20 -> #NAME? | O20: =IF(N20=0,"",K20/N20) -> #NAME? | P20: ='01_INPUTS'!B9*N20-K20 -> #NAME? | Q20: =IF(P20>0,1,0) -> #NAME? | R20: 0.55061992 | S20: 0.51293799 | T20: 0.30710693 | U20: 0.31237237 | V20: 0.25454317 | W20: 0.59673006 | X20: 0.39574339
A21: 20 | B21: =_xludf.BETA.INV(R21,'04_PSA_INPUTS'!H5,'04_PSA_INPUTS'!I5) -> #NAME? | C21: =_xludf.BETA.INV(S21,'04_PSA_INPUTS'!H6,'04_PSA_INPUTS'!I6) -> #NAME? | D21: =_xludf.GAMMA.INV(T21,'04_PSA_INPUTS'!H7,'04_PSA_INPUTS'!I7) -> #NAME? | E21: =_xludf.GAMMA.INV(U21,'04_PSA_INPUTS'!H8,'04_PSA_INPUTS'!I8) -> #NAME? | F21: =_xludf.GAMMA.INV(V21,'04_PSA_INPUTS'!H9,'04_PSA_INPUTS'!I9) -> #NAME? | G21: =_xludf.BETA.INV(W21,'04_PSA_INPUTS'!H10,'04_PSA_INPUTS'!I10) -> #NAME? | H21: =_xludf.BETA.INV(X21,'04_PSA_INPUTS'!H11,'04_PSA_INPUTS'!I11) -> #NAME? | I21: =D21+B21*F21+'01_INPUTS'!B20 -> #NAME? | J21: =E21+C21*F21+'01_INPUTS'!B21 -> #NAME? | K21: =I21-J21 -> #NAME? | L21: =G21-B21*H21 -> #NAME? | M21: =G21-C21*H21 -> #NAME? | N21: =L21-M21 -> #NAME? | O21: =IF(N21=0,"",K21/N21) -> #NAME? | P21: ='01_INPUTS'!B9*N21-K21 -> #NAME? | Q21: =IF(P21>0,1,0) -> #NAME? | R21: 0.22088744 | S21: 0.6453192 | T21: 0.93834112 | U21: 0.1619097 | V21: 0.74984376 | W21: 0.12902333 | X21: 0.037859896
A22: 21 | B22: =_xludf.BETA.INV(R22,'04_PSA_INPUTS'!H5,'04_PSA_INPUTS'!I5) -> #NAME? | C22: =_xludf.BETA.INV(S22,'04_PSA_INPUTS'!H6,'04_PSA_INPUTS'!I6) -> #NAME? | D22: =_xludf.GAMMA.INV(T22,'04_PSA_INPUTS'!H7,'04_PSA_INPUTS'!I7) -> #NAME? | E22: =_xludf.GAMMA.INV(U22,'04_PSA_INPUTS'!H8,'04_PSA_INPUTS'!I8) -> #NAME? | F22: =_xludf.GAMMA.INV(V22,'04_PSA_INPUTS'!H9,'04_PSA_INPUTS'!I9) -> #NAME? | G22: =_xludf.BETA.INV(W22,'04_PSA_INPUTS'!H10,'04_PSA_INPUTS'!I10) -> #NAME? | H22: =_xludf.BETA.INV(X22,'04_PSA_INPUTS'!H11,'04_PSA_INPUTS'!I11) -> #NAME? | I22: =D22+B22*F22+'01_INPUTS'!B20 -> #NAME? | J22: =E22+C22*F22+'01_INPUTS'!B21 -> #NAME? | K22: =I22-J22 -> #NAME? | L22: =G22-B22*H22 -> #NAME? | M22: =G22-C22*H22 -> #NAME? | N22: =L22-M22 -> #NAME? | O22: =IF(N22=0,"",K22/N22) -> #NAME? | P22: ='01_INPUTS'!B9*N22-K22 -> #NAME? | Q22: =IF(P22>0,1,0) -> #NAME? | R22: 0.53822981 | S22: 0.87924275 | T22: 0.57269545 | U22: 0.058258447 | V22: 0.79198635 | W22: 0.85815303 | X22: 0.85617431
A23: 22 | B23: =_xludf.BETA.INV(R23,'04_PSA_INPUTS'!H5,'04_PSA_INPUTS'!I5) -> #NAME? | C23: =_xludf.BETA.INV(S23,'04_PSA_INPUTS'!H6,'04_PSA_INPUTS'!I6) -> #NAME? | D23: =_xludf.GAMMA.INV(T23,'04_PSA_INPUTS'!H7,'04_PSA_INPUTS'!I7) -> #NAME? | E23: =_xludf.GAMMA.INV(U23,'04_PSA_INPUTS'!H8,'04_PSA_INPUTS'!I8) -> #NAME? | F23: =_xludf.GAMMA.INV(V23,'04_PSA_INPUTS'!H9,'04_PSA_INPUTS'!I9) -> #NAME? | G23: =_xludf.BETA.INV(W23,'04_PSA_INPUTS'!H10,'04_PSA_INPUTS'!I10) -> #NAME? | H23: =_xludf.BETA.INV(X23,'04_PSA_INPUTS'!H11,'04_PSA_INPUTS'!I11) -> #NAME? | I23: =D23+B23*F23+'01_INPUTS'!B20 -> #NAME? | J23: =E23+C23*F23+'01_INPUTS'!B21 -> #NAME? | K23: =I23-J23 -> #NAME? | L23: =G23-B23*H23 -> #NAME? | M23: =G23-C23*H23 -> #NAME? | N23: =L23-M23 -> #NAME? | O23: =IF(N23=0,"",K23/N23) -> #NAME? | P23: ='01_INPUTS'!B9*N23-K23 -> #NAME? | Q23: =IF(P23>0,1,0) -> #NAME? | R23: 0.38472014 | S23: 0.6902828 | T23: 0.3251801 | U23: 0.21952724 | V23: 0.77691693 | W23: 0.74446116 | X23: 0.078943223
A24: 23 | B24: =_xludf.BETA.INV(R24,'04_PSA_INPUTS'!H5,'04_PSA_INPUTS'!I5) -> #NAME? | C24: =_xludf.BETA.INV(S24,'04_PSA_INPUTS'!H6,'04_PSA_INPUTS'!I6) -> #NAME? | D24: =_xludf.GAMMA.INV(T24,'04_PSA_INPUTS'!H7,'04_PSA_INPUTS'!I7) -> #NAME? | E24: =_xludf.GAMMA.INV(U24,'04_PSA_INPUTS'!H8,'04_PSA_INPUTS'!I8) -> #NAME? | F24: =_xludf.GAMMA.INV(V24,'04_PSA_INPUTS'!H9,'04_PSA_INPUTS'!I9) -> #NAME? | G24: =_xludf.BETA.INV(W24,'04_PSA_INPUTS'!H10,'04_PSA_INPUTS'!I10) -> #NAME? | H24: =_xludf.BETA.INV(X24,'04_PSA_INPUTS'!H11,'04_PSA_INPUTS'!I11) -> #NAME? | I24: =D24+B24*F24+'01_INPUTS'!B20 -> #NAME? | J24: =E24+C24*F24+'01_INPUTS'!B21 -> #NAME? | K24: =I24-J24 -> #NAME? | L24: =G24-B24*H24 -> #NAME? | M24: =G24-C24*H24 -> #NAME? | N24: =L24-M24 -> #NAME? | O24: =IF(N24=0,"",K24/N24) -> #NAME? | P24: ='01_INPUTS'!B9*N24-K24 -> #NAME? | Q24: =IF(P24>0,1,0) -> #NAME? | R24: 0.80523276 | S24: 0.15439995 | T24: 0.18937044 | U24: 0.40894322 | V24: 0.87333946 | W24: 0.89972263 | X24: 0.040390044
A25: 24 | B25: =_xludf.BETA.INV(R25,'04_PSA_INPUTS'!H5,'04_PSA_INPUTS'!I5) -> #NAME? | C25: =_xludf.BETA.INV(S25,'04_PSA_INPUTS'!H6,'04_PSA_INPUTS'!I6) -> #NAME? | D25: =_xludf.GAMMA.INV(T25,'04_PSA_INPUTS'!H7,'04_PSA_INPUTS'!I7) -> #NAME? | E25: =_xludf.GAMMA.INV(U25,'04_PSA_INPUTS'!H8,'04_PSA_INPUTS'!I8) -> #NAME? | F25: =_xludf.GAMMA.INV(V25,'04_PSA_INPUTS'!H9,'04_PSA_INPUTS'!I9) -> #NAME? | G25: =_xludf.BETA.INV(W25,'04_PSA_INPUTS'!H10,'04_PSA_INPUTS'!I10) -> #NAME? | H25: =_xludf.BETA.INV(X25,'04_PSA_INPUTS'!H11,'04_PSA_INPUTS'!I11) -> #NAME? | I25: =D25+B25*F25+'01_INPUTS'!B20 -> #NAME? | J25: =E25+C25*F25+'01_INPUTS'!B21 -> #NAME? | K25: =I25-J25 -> #NAME? | L25: =G25-B25*H25 -> #NAME? | M25: =G25-C25*H25 -> #NAME? | N25: =L25-M25 -> #NAME? | O25: =IF(N25=0,"",K25/N25) -> #NAME? | P25: ='01_INPUTS'!B9*N25-K25 -> #NAME? | Q25: =IF(P25>0,1,0) -> #NAME? | R25: 0.33599298 | S25: 0.28770193 | T25: 0.17793842 | U25: 0.88799565 | V25: 0.99012109 | W25: 0.91350429 | X25: 0.66642391
A26: 25 | B26: =_xludf.BETA.INV(R26,'04_PSA_INPUTS'!H5,'04_PSA_INPUTS'!I5) -> #NAME? | C26: =_xludf.BETA.INV(S26,'04_PSA_INPUTS'!H6,'04_PSA_INPUTS'!I6) -> #NAME? | D26: =_xludf.GAMMA.INV(T26,'04_PSA_INPUTS'!H7,'04_PSA_INPUTS'!I7) -> #NAME? | E26: =_xludf.GAMMA.INV(U26,'04_PSA_INPUTS'!H8,'04_PSA_INPUTS'!I8) -> #NAME? | F26: =_xludf.GAMMA.INV(V26,'04_PSA_INPUTS'!H9,'04_PSA_INPUTS'!I9) -> #NAME? | G26: =_xludf.BETA.INV(W26,'04_PSA_INPUTS'!H10,'04_PSA_INPUTS'!I10) -> #NAME? | H26: =_xludf.BETA.INV(X26,'04_PSA_INPUTS'!H11,'04_PSA_INPUTS'!I11) -> #NAME? | I26: =D26+B26*F26+'01_INPUTS'!B20 -> #NAME? | J26: =E26+C26*F26+'01_INPUTS'!B21 -> #NAME? | K26: =I26-J26 -> #NAME? | L26: =G26-B26*H26 -> #NAME? | M26: =G26-C26*H26 -> #NAME? | N26: =L26-M26 -> #NAME? | O26: =IF(N26=0,"",K26/N26) -> #NAME? | P26: ='01_INPUTS'!B9*N26-K26 -> #NAME? | Q26: =IF(P26>0,1,0) -> #NAME? | R26: 0.67887075 | S26: 0.7724005 | T26: 0.46824686 | U26: 0.042103337 | V26: 0.3706097 | W26: 0.83133215 | X26: 0.2904357
A27: 26 | B27: =_xludf.BETA.INV(R27,'04_PSA_INPUTS'!H5,'04_PSA_INPUTS'!I5) -> #NAME? | C27: =_xludf.BETA.INV(S27,'04_PSA_INPUTS'!H6,'04_PSA_INPUTS'!I6) -> #NAME? | D27: =_xludf.GAMMA.INV(T27,'04_PSA_INPUTS'!H7,'04_PSA_INPUTS'!I7) -> #NAME? | E27: =_xludf.GAMMA.INV(U27,'04_PSA_INPUTS'!H8,'04_PSA_INPUTS'!I8) -> #NAME? | F27: =_xludf.GAMMA.INV(V27,'04_PSA_INPUTS'!H9,'04_PSA_INPUTS'!I9) -> #NAME? | G27: =_xludf.BETA.INV(W27,'04_PSA_INPUTS'!H10,'04_PSA_INPUTS'!I10) -> #NAME? | H27: =_xludf.BETA.INV(X27,'04_PSA_INPUTS'!H11,'04_PSA_INPUTS'!I11) -> #NAME? | I27: =D27+B27*F27+'01_INPUTS'!B20 -> #NAME? | J27: =E27+C27*F27+'01_INPUTS'!B21 -> #NAME? | K27: =I27-J27 -> #NAME? | L27: =G27-B27*H27 -> #NAME? | M27: =G27-C27*H27 -> #NAME? | N27: =L27-M27 -> #NAME? | O27: =IF(N27=0,"",K27/N27) -> #NAME? | P27: ='01_INPUTS'!B9*N27-K27 -> #NAME? | Q27: =IF(P27>0,1,0) -> #NAME? | R27: 0.93637224 | S27: 0.71798151 | T27: 0.17751263 | U27: 0.11121219 | V27: 0.029119569 | W27: 0.72373369 | X27: 0.46903111
A28: 27 | B28: =_xludf.BETA.INV(R28,'04_PSA_INPUTS'!H5,'04_PSA_INPUTS'!I5) -> #NAME? | C28: =_xludf.BETA.INV(S28,'04_PSA_INPUTS'!H6,'04_PSA_INPUTS'!I6) -> #NAME? | D28: =_xludf.GAMMA.INV(T28,'04_PSA_INPUTS'!H7,'04_PSA_INPUTS'!I7) -> #NAME? | E28: =_xludf.GAMMA.INV(U28,'04_PSA_INPUTS'!H8,'04_PSA_INPUTS'!I8) -> #NAME? | F28: =_xludf.GAMMA.INV(V28,'04_PSA_INPUTS'!H9,'04_PSA_INPUTS'!I9) -> #NAME? | G28: =_xludf.BETA.INV(W28,'04_PSA_INPUTS'!H10,'04_PSA_INPUTS'!I10) -> #NAME? | H28: =_xludf.BETA.INV(X28,'04_PSA_INPUTS'!H11,'04_PSA_INPUTS'!I11) -> #NAME? | I28: =D28+B28*F28+'01_INPUTS'!B20 -> #NAME? | J28: =E28+C28*F28+'01_INPUTS'!B21 -> #NAME? | K28: =I28-J28 -> #NAME? | L28: =G28-B28*H28 -> #NAME? | M28: =G28-C28*H28 -> #NAME? | N28: =L28-M28 -> #NAME? | O28: =IF(N28=0,"",K28/N28) -> #NAME? | P28: ='01_INPUTS'!B9*N28-K28 -> #NAME? | Q28: =IF(P28>0,1,0) -> #NAME? | R28: 0.47613508 | S28: 0.8793365 | T28: 0.70249098 | U28: 0.13945042 | V28: 0.21436374 | W28: 0.36085462 | X28: 0.62827811
A29: 28 | B29: =_xludf.BETA.INV(R29,'04_PSA_INPUTS'!H5,'04_PSA_INPUTS'!I5) -> #NAME? | C29: =_xludf.BETA.INV(S29,'04_PSA_INPUTS'!H6,'04_PSA_INPUTS'!I6) -> #NAME? | D29: =_xludf.GAMMA.INV(T29,'04_PSA_INPUTS'!H7,'04_PSA_INPUTS'!I7) -> #NAME? | E29: =_xludf.GAMMA.INV(U29,'04_PSA_INPUTS'!H8,'04_PSA_INPUTS'!I8) -> #NAME? | F29: =_xludf.GAMMA.INV(V29,'04_PSA_INPUTS'!H9,'04_PSA_INPUTS'!I9) -> #NAME? | G29: =_xludf.BETA.INV(W29,'04_PSA_INPUTS'!H10,'04_PSA_INPUTS'!I10) -> #NAME? | H29: =_xludf.BETA.INV(X29,'04_PSA_INPUTS'!H11,'04_PSA_INPUTS'!I11) -> #NAME? | I29: =D29+B29*F29+'01_INPUTS'!B20 -> #NAME? | J29: =E29+C29*F29+'01_INPUTS'!B21 -> #NAME? | K29: =I29-J29 -> #NAME? | L29: =G29-B29*H29 -> #NAME? | M29: =G29-C29*H29 -> #NAME? | N29: =L29-M29 -> #NAME? | O29: =IF(N29=0,"",K29/N29) -> #NAME? | P29: ='01_INPUTS'!B9*N29-K29 -> #NAME? | Q29: =IF(P29>0,1,0) -> #NAME? | R29: 0.16209288 | S29: 0.030991339 | T29: 0.75910468 | U29: 0.35181342 | V29: 0.046143564 | W29: 0.89630331 | X29: 0.80500658
A30: 29 | B30: =_xludf.BETA.INV(R30,'04_PSA_INPUTS'!H5,'04_PSA_INPUTS'!I5) -> #NAME? | C30: =_xludf.BETA.INV(S30,'04_PSA_INPUTS'!H6,'04_PSA_INPUTS'!I6) -> #NAME? | D30: =_xludf.GAMMA.INV(T30,'04_PSA_INPUTS'!H7,'04_PSA_INPUTS'!I7) -> #NAME? | E30: =_xludf.GAMMA.INV(U30,'04_PSA_INPUTS'!H8,'04_PSA_INPUTS'!I8) -> #NAME? | F30: =_xludf.GAMMA.INV(V30,'04_PSA_INPUTS'!H9,'04_PSA_INPUTS'!I9) -> #NAME? | G30: =_xludf.BETA.INV(W30,'04_PSA_INPUTS'!H10,'04_PSA_INPUTS'!I10) -> #NAME? | H30: =_xludf.BETA.INV(X30,'04_PSA_INPUTS'!H11,'04_PSA_INPUTS'!I11) -> #NAME? | I30: =D30+B30*F30+'01_INPUTS'!B20 -> #NAME? | J30: =E30+C30*F30+'01_INPUTS'!B21 -> #NAME? | K30: =I30-J30 -> #NAME? | L30: =G30-B30*H30 -> #NAME? | M30: =G30-C30*H30 -> #NAME? | N30: =L30-M30 -> #NAME? | O30: =IF(N30=0,"",K30/N30) -> #NAME? | P30: ='01_INPUTS'!B9*N30-K30 -> #NAME? | Q30: =IF(P30>0,1,0) -> #NAME? | R30: 0.68381136 | S30: 0.80275786 | T30: 0.011304724 | U30: 0.94317518 | V30: 0.62026487 | W30: 0.45494096 | X30: 0.062180173
A31: 30 | B31: =_xludf.BETA.INV(R31,'04_PSA_INPUTS'!H5,'04_PSA_INPUTS'!I5) -> #NAME? | C31: =_xludf.BETA.INV(S31,'04_PSA_INPUTS'!H6,'04_PSA_INPUTS'!I6) -> #NAME? | D31: =_xludf.GAMMA.INV(T31,'04_PSA_INPUTS'!H7,'04_PSA_INPUTS'!I7) -> #NAME? | E31: =_xludf.GAMMA.INV(U31,'04_PSA_INPUTS'!H8,'04_PSA_INPUTS'!I8) -> #NAME? | F31: =_xludf.GAMMA.INV(V31,'04_PSA_INPUTS'!H9,'04_PSA_INPUTS'!I9) -> #NAME? | G31: =_xludf.BETA.INV(W31,'04_PSA_INPUTS'!H10,'04_PSA_INPUTS'!I10) -> #NAME? | H31: =_xludf.BETA.INV(X31,'04_PSA_INPUTS'!H11,'04_PSA_INPUTS'!I11) -> #NAME? | I31: =D31+B31*F31+'01_INPUTS'!B20 -> #NAME? | J31: =E31+C31*F31+'01_INPUTS'!B21 -> #NAME? | K31: =I31-J31 -> #NAME? | L31: =G31-B31*H31 -> #NAME? | M31: =G31-C31*H31 -> #NAME? | N31: =L31-M31 -> #NAME? | O31: =IF(N31=0,"",K31/N31) -> #NAME? | P31: ='01_INPUTS'!B9*N31-K31 -> #NAME? | Q31: =IF(P31>0,1,0) -> #NAME? | R31: 0.36028325 | S31: 0.099905874 | T31: 0.78880939 | U31: 0.17113769 | V31: 0.79248085 | W31: 0.80271818 | X31: 0.80431883
A32: 31 | B32: =_xludf.BETA.INV(R32,'04_PSA_INPUTS'!H5,'04_PSA_INPUTS'!I5) -> #NAME? | C32: =_xludf.BETA.INV(S32,'04_PSA_INPUTS'!H6,'04_PSA_INPUTS'!I6) -> #NAME? | D32: =_xludf.GAMMA.INV(T32,'04_PSA_INPUTS'!H7,'04_PSA_INPUTS'!I7) -> #NAME? | E32: =_xludf.GAMMA.INV(U32,'04_PSA_INPUTS'!H8,'04_PSA_INPUTS'!I8) -> #NAME? | F32: =_xludf.GAMMA.INV(V32,'04_PSA_INPUTS'!H9,'04_PSA_INPUTS'!I9) -> #NAME? | G32: =_xludf.BETA.INV(W32,'04_PSA_INPUTS'!H10,'04_PSA_INPUTS'!I10) -> #NAME? | H32: =_xludf.BETA.INV(X32,'04_PSA_INPUTS'!H11,'04_PSA_INPUTS'!I11) -> #NAME? | I32: =D32+B32*F32+'01_INPUTS'!B20 -> #NAME? | J32: =E32+C32*F32+'01_INPUTS'!B21 -> #NAME? | K32: =I32-J32 -> #NAME? | L32: =G32-B32*H32 -> #NAME? | M32: =G32-C32*H32 -> #NAME? | N32: =L32-M32 -> #NAME? | O32: =IF(N32=0,"",K32/N32) -> #NAME? | P32: ='01_INPUTS'!B9*N32-K32 -> #NAME? | Q32: =IF(P32>0,1,0) -> #NAME? | R32: 0.082159915 | S32: 0.6993287 | T32: 0.42707174 | U32: 0.85733852 | V32: 0.65570965 | W32: 0.11014309 | X32: 0.24447316
A33: 32 | B33: =_xludf.BETA.INV(R33,'04_PSA_INPUTS'!H5,'04_PSA_INPUTS'!I5) -> #NAME? | C33: =_xludf.BETA.INV(S33,'04_PSA_INPUTS'!H6,'04_PSA_INPUTS'!I6) -> #NAME? | D33: =_xludf.GAMMA.INV(T33,'04_PSA_INPUTS'!H7,'04_PSA_INPUTS'!I7) -> #NAME? | E33: =_xludf.GAMMA.INV(U33,'04_PSA_INPUTS'!H8,'04_PSA_INPUTS'!I8) -> #NAME? | F33: =_xludf.GAMMA.INV(V33,'04_PSA_INPUTS'!H9,'04_PSA_INPUTS'!I9) -> #NAME? | G33: =_xludf.BETA.INV(W33,'04_PSA_INPUTS'!H10,'04_PSA_INPUTS'!I10) -> #NAME? | H33: =_xludf.BETA.INV(X33,'04_PSA_INPUTS'!H11,'04_PSA_INPUTS'!I11) -> #NAME? | I33: =D33+B33*F33+'01_INPUTS'!B20 -> #NAME? | J33: =E33+C33*F33+'01_INPUTS'!B21 -> #NAME? | K33: =I33-J33 -> #NAME? | L33: =G33-B33*H33 -> #NAME? | M33: =G33-C33*H33 -> #NAME? | N33: =L33-M33 -> #NAME? | O33: =IF(N33=0,"",K33/N33) -> #NAME? | P33: ='01_INPUTS'!B9*N33-K33 -> #NAME? | Q33: =IF(P33>0,1,0) -> #NAME? | R33: 0.52799638 | S33: 0.43523017 | T33: 0.37641143 | U33: 0.20478291 | V33: 0.13294651 | W33: 0.13275171 | X33: 0.46114236
A34: 33 | B34: =_xludf.BETA.INV(R34,'04_PSA_INPUTS'!H5,'04_PSA_INPUTS'!I5) -> #NAME? | C34: =_xludf.BETA.INV(S34,'04_PSA_INPUTS'!H6,'04_PSA_INPUTS'!I6) -> #NAME? | D34: =_xludf.GAMMA.INV(T34,'04_PSA_INPUTS'!H7,'04_PSA_INPUTS'!I7) -> #NAME? | E34: =_xludf.GAMMA.INV(U34,'04_PSA_INPUTS'!H8,'04_PSA_INPUTS'!I8) -> #NAME? | F34: =_xludf.GAMMA.INV(V34,'04_PSA_INPUTS'!H9,'04_PSA_INPUTS'!I9) -> #NAME? | G34: =_xludf.BETA.INV(W34,'04_PSA_INPUTS'!H10,'04_PSA_INPUTS'!I10) -> #NAME? | H34: =_xludf.BETA.INV(X34,'04_PSA_INPUTS'!H11,'04_PSA_INPUTS'!I11) -> #NAME? | I34: =D34+B34*F34+'01_INPUTS'!B20 -> #NAME? | J34: =E34+C34*F34+'01_INPUTS'!B21 -> #NAME? | K34: =I34-J34 -> #NAME? | L34: =G34-B34*H34 -> #NAME? | M34: =G34-C34*H34 -> #NAME? | N34: =L34-M34 -> #NAME? | O34: =IF(N34=0,"",K34/N34) -> #NAME? | P34: ='01_INPUTS'!B9*N34-K34 -> #NAME? | Q34: =IF(P34>0,1,0) -> #NAME? | R34: 0.95489144 | S34: 0.43646426 | T34: 0.068110791 | U34: 0.40751075 | V34: 0.84810984 | W34: 0.24183545 | X34: 0.1792598
A35: 34 | B35: =_xludf.BETA.INV(R35,'04_PSA_INPUTS'!H5,'04_PSA_INPUTS'!I5) -> #NAME? | C35: =_xludf.BETA.INV(S35,'04_PSA_INPUTS'!H6,'04_PSA_INPUTS'!I6) -> #NAME? | D35: =_xludf.GAMMA.INV(T35,'04_PSA_INPUTS'!H7,'04_PSA_INPUTS'!I7) -> #NAME? | E35: =_xludf.GAMMA.INV(U35,'04_PSA_INPUTS'!H8,'04_PSA_INPUTS'!I8) -> #NAME? | F35: =_xludf.GAMMA.INV(V35,'04_PSA_INPUTS'!H9,'04_PSA_INPUTS'!I9) -> #NAME? | G35: =_xludf.BETA.INV(W35,'04_PSA_INPUTS'!H10,'04_PSA_INPUTS'!I10) -> #NAME? | H35: =_xludf.BETA.INV(X35,'04_PSA_INPUTS'!H11,'04_PSA_INPUTS'!I11) -> #NAME? | I35: =D35+B35*F35+'01_INPUTS'!B20 -> #NAME? | J35: =E35+C35*F35+'01_INPUTS'!B21 -> #NAME? | K35: =I35-J35 -> #NAME? | L35: =G35-B35*H35 -> #NAME? | M35: =G35-C35*H35 -> #NAME? | N35: =L35-M35 -> #NAME? | O35: =IF(N35=0,"",K35/N35) -> #NAME? | P35: ='01_INPUTS'!B9*N35-K35 -> #NAME? | Q35: =IF(P35>0,1,0) -> #NAME? | R35: 0.14766824 | S35: 0.68838141 | T35: 0.17783968 | U35: 0.81518968 | V35: 0.1000904 | W35: 0.061739107 | X35: 0.10379789
A36: 35 | B36: =_xludf.BETA.INV(R36,'04_PSA_INPUTS'!H5,'04_PSA_INPUTS'!I5) -> #NAME? | C36: =_xludf.BETA.INV(S36,'04_PSA_INPUTS'!H6,'04_PSA_INPUTS'!I6) -> #NAME? | D36: =_xludf.GAMMA.INV(T36,'04_PSA_INPUTS'!H7,'04_PSA_INPUTS'!I7) -> #NAME? | E36: =_xludf.GAMMA.INV(U36,'04_PSA_INPUTS'!H8,'04_PSA_INPUTS'!I8) -> #NAME? | F36: =_xludf.GAMMA.INV(V36,'04_PSA_INPUTS'!H9,'04_PSA_INPUTS'!I9) -> #NAME? | G36: =_xludf.BETA.INV(W36,'04_PSA_INPUTS'!H10,'04_PSA_INPUTS'!I10) -> #NAME? | H36: =_xludf.BETA.INV(X36,'04_PSA_INPUTS'!H11,'04_PSA_INPUTS'!I11) -> #NAME? | I36: =D36+B36*F36+'01_INPUTS'!B20 -> #NAME? | J36: =E36+C36*F36+'01_INPUTS'!B21 -> #NAME? | K36: =I36-J36 -> #NAME? | L36: =G36-B36*H36 -> #NAME? | M36: =G36-C36*H36 -> #NAME? | N36: =L36-M36 -> #NAME? | O36: =IF(N36=0,"",K36/N36) -> #NAME? | P36: ='01_INPUTS'!B9*N36-K36 -> #NAME? | Q36: =IF(P36>0,1,0) -> #NAME? | R36: 0.49467662 | S36: 0.58229837 | T36: 0.48921708 | U36: 0.47409887 | V36: 0.99543186 | W36: 0.26044876 | X36: 0.7436664
A37: 36 | B37: =_xludf.BETA.INV(R37,'04_PSA_INPUTS'!H5,'04_PSA_INPUTS'!I5) -> #NAME? | C37: =_xludf.BETA.INV(S37,'04_PSA_INPUTS'!H6,'04_PSA_INPUTS'!I6) -> #NAME? | D37: =_xludf.GAMMA.INV(T37,'04_PSA_INPUTS'!H7,'04_PSA_INPUTS'!I7) -> #NAME? | E37: =_xludf.GAMMA.INV(U37,'04_PSA_INPUTS'!H8,'04_PSA_INPUTS'!I8) -> #NAME? | F37: =_xludf.GAMMA.INV(V37,'04_PSA_INPUTS'!H9,'04_PSA_INPUTS'!I9) -> #NAME? | G37: =_xludf.BETA.INV(W37,'04_PSA_INPUTS'!H10,'04_PSA_INPUTS'!I10) -> #NAME? | H37: =_xludf.BETA.INV(X37,'04_PSA_INPUTS'!H11,'04_PSA_INPUTS'!I11) -> #NAME? | I37: =D37+B37*F37+'01_INPUTS'!B20 -> #NAME? | J37: =E37+C37*F37+'01_INPUTS'!B21 -> #NAME? | K37: =I37-J37 -> #NAME? | L37: =G37-B37*H37 -> #NAME? | M37: =G37-C37*H37 -> #NAME? | N37: =L37-M37 -> #NAME? | O37: =IF(N37=0,"",K37/N37) -> #NAME? | P37: ='01_INPUTS'!B9*N37-K37 -> #NAME? | Q37: =IF(P37>0,1,0) -> #NAME? | R37: 0.60412116 | S37: 0.15550622 | T37: 0.49846658 | U37: 0.82374349 | V37: 0.18869707 | W37: 0.14194688 | X37: 0.76720174
A38: 37 | B38: =_xludf.BETA.INV(R38,'04_PSA_INPUTS'!H5,'04_PSA_INPUTS'!I5) -> #NAME? | C38: =_xludf.BETA.INV(S38,'04_PSA_INPUTS'!H6,'04_PSA_INPUTS'!I6) -> #NAME? | D38: =_xludf.GAMMA.INV(T38,'04_PSA_INPUTS'!H7,'04_PSA_INPUTS'!I7) -> #NAME? | E38: =_xludf.GAMMA.INV(U38,'04_PSA_INPUTS'!H8,'04_PSA_INPUTS'!I8) -> #NAME? | F38: =_xludf.GAMMA.INV(V38,'04_PSA_INPUTS'!H9,'04_PSA_INPUTS'!I9) -> #NAME? | G38: =_xludf.BETA.INV(W38,'04_PSA_INPUTS'!H10,'04_PSA_INPUTS'!I10) -> #NAME? | H38: =_xludf.BETA.INV(X38,'04_PSA_INPUTS'!H11,'04_PSA_INPUTS'!I11) -> #NAME? | I38: =D38+B38*F38+'01_INPUTS'!B20 -> #NAME? | J38: =E38+C38*F38+'01_INPUTS'!B21 -> #NAME? | K38: =I38-J38 -> #NAME? | L38: =G38-B38*H38 -> #NAME? | M38: =G38-C38*H38 -> #NAME? | N38: =L38-M38 -> #NAME? | O38: =IF(N38=0,"",K38/N38) -> #NAME? | P38: ='01_INPUTS'!B9*N38-K38 -> #NAME? | Q38: =IF(P38>0,1,0) -> #NAME? | R38: 0.74376619 | S38: 0.46219565 | T38: 0.71656598 | U38: 0.59107143 | V38: 0.93136511 | W38: 0.54263121 | X38: 0.77302049
A39: 38 | B39: =_xludf.BETA.INV(R39,'04_PSA_INPUTS'!H5,'04_PSA_INPUTS'!I5) -> #NAME? | C39: =_xludf.BETA.INV(S39,'04_PSA_INPUTS'!H6,'04_PSA_INPUTS'!I6) -> #NAME? | D39: =_xludf.GAMMA.INV(T39,'04_PSA_INPUTS'!H7,'04_PSA_INPUTS'!I7) -> #NAME? | E39: =_xludf.GAMMA.INV(U39,'04_PSA_INPUTS'!H8,'04_PSA_INPUTS'!I8) -> #NAME? | F39: =_xludf.GAMMA.INV(V39,'04_PSA_INPUTS'!H9,'04_PSA_INPUTS'!I9) -> #NAME? | G39: =_xludf.BETA.INV(W39,'04_PSA_INPUTS'!H10,'04_PSA_INPUTS'!I10) -> #NAME? | H39: =_xludf.BETA.INV(X39,'04_PSA_INPUTS'!H11,'04_PSA_INPUTS'!I11) -> #NAME? | I39: =D39+B39*F39+'01_INPUTS'!B20 -> #NAME? | J39: =E39+C39*F39+'01_INPUTS'!B21 -> #NAME? | K39: =I39-J39 -> #NAME? | L39: =G39-B39*H39 -> #NAME? | M39: =G39-C39*H39 -> #NAME? | N39: =L39-M39 -> #NAME? | O39: =IF(N39=0,"",K39/N39) -> #NAME? | P39: ='01_INPUTS'!B9*N39-K39 -> #NAME? | Q39: =IF(P39>0,1,0) -> #NAME? | R39: 0.76275777 | S39: 0.26780302 | T39: 0.7781536 | U39: 0.04043909 | V39: 0.32147946 | W39: 0.83398546 | X39: 0.8773302
A40: 39 | B40: =_xludf.BETA.INV(R40,'04_PSA_INPUTS'!H5,'04_PSA_INPUTS'!I5) -> #NAME? | C40: =_xludf.BETA.INV(S40,'04_PSA_INPUTS'!H6,'04_PSA_INPUTS'!I6) -> #NAME? | D40: =_xludf.GAMMA.INV(T40,'04_PSA_INPUTS'!H7,'04_PSA_INPUTS'!I7) -> #NAME? | E40: =_xludf.GAMMA.INV(U40,'04_PSA_INPUTS'!H8,'04_PSA_INPUTS'!I8) -> #NAME? | F40: =_xludf.GAMMA.INV(V40,'04_PSA_INPUTS'!H9,'04_PSA_INPUTS'!I9) -> #NAME? | G40: =_xludf.BETA.INV(W40,'04_PSA_INPUTS'!H10,'04_PSA_INPUTS'!I10) -> #NAME? | H40: =_xludf.BETA.INV(X40,'04_PSA_INPUTS'!H11,'04_PSA_INPUTS'!I11) -> #NAME? | I40: =D40+B40*F40+'01_INPUTS'!B20 -> #NAME? | J40: =E40+C40*F40+'01_INPUTS'!B21 -> #NAME? | K40: =I40-J40 -> #NAME? | L40: =G40-B40*H40 -> #NAME? | M40: =G40-C40*H40 -> #NAME? | N40: =L40-M40 -> #NAME? | O40: =IF(N40=0,"",K40/N40) -> #NAME? | P40: ='01_INPUTS'!B9*N40-K40 -> #NAME? | Q40: =IF(P40>0,1,0) -> #NAME? | R40: 0.59351966 | S40: 0.17065936 | T40: 0.46072244 | U40: 0.98115048 | V40: 0.10345178 | W40: 0.011356538 | X40: 0.50443445
...

Sheet 06_CE_PLANE_CEAC
A1: Cost-Effectiveness Plane and CEAC | B1: Cost-Effectiveness Plane and CEAC | C1: Cost-Effectiveness Plane and CEAC | D1: Cost-Effectiveness Plane and CEAC | E1: Cost-Effectiveness Plane and CEAC | F1: Cost-Effectiveness Plane and CEAC | G1: Cost-Effectiveness Plane and CEAC | H1: Cost-Effectiveness Plane and CEAC | I1: Cost-Effectiveness Plane and CEAC | J1: Cost-Effectiveness Plane and CEAC | K1: Cost-Effectiveness Plane and CEAC | L1: Cost-Effectiveness Plane and CEAC | M1: Cost-Effectiveness Plane and CEAC | N1: Cost-Effectiveness Plane and CEAC
